To fix the failing test and make it pass, you need to modify the error enum `ParsePosNonzeroError` to include a variant for `ParseInt`. Here's the updated code:

### Updated Enum and `parse` function:

```rust
#[derive(Debug)]
enum ParsePosNonzeroError {
    InvalidInput,
    ParseInt(std::num::ParseIntError), // New variant for parse errors
    CreationError(CreationError),
}

impl From<std::num::ParseIntError> for ParsePosNonzeroError {
    fn from(err: std::num::ParseIntError) -> Self {
        ParsePosNonzeroError::ParseInt(err)
    }
}

impl PositiveNonzeroInteger {
    fn parse(s: &str) -> Result<Self, ParsePosNonzeroError> {
        let x: i64 = s.parse()?; // Use `?` to propagate parse errors
        PositiveNonzeroInteger::new(x).map_err(ParsePosNonzeroError::from_creation)
    }
}
```

### Test Update:

The test expects a `ParseInt` error to be returned when the input is not a valid number. Here's the test case:

```rust
#[test]
fn test_parse_error() {
    assert!(matches!(
        PositiveNonzeroInteger::parse("not a number"),
        Err(ParsePosNonzeroError::ParseInt(_)),
    ));
}
```

### Explanation:

- The `ParseInt` variant in the error enum now handles integer parsing errors from the `std::num::ParseIntError` type.
- The `parse` method has been updated to use `?`, which automatically converts `ParseIntError` into `ParsePosNonzeroError::ParseInt`.
